Workbook

Sheet Generación Bruta
B2: Comisión Nacional de Energía
B3: Sistema de Información Energética Nacional
B4: Generación bruta de energía eléctrica según central y Mes, 2024
B5: (en kWh)
B7: Central | C7: Enero | D7: Febrero | E7: Marzo | F7: Abril | G7: Mayo | H7: Junio | I7: Julio | J7: Agosto | K7: Septiembre | L7: Octubre | M7: Noviembre | N7: Diciembre | O7: Total
B8: AES Andrés | C8: 1.0719388e+08 | D8: 1.6609717e+08 | E8: 1.9310047e+08 | F8: 1.6242352e+08 | G8: 1.5837495e+08 | H8: 1.4206139e+08 | I8: 1.8663699e+08 | J8: 1.9106661e+08 | K8: 1.8437528e+08 | L8: 1.9780579e+08 | M8: 1.7244009e+08 | N8: 1.3346808e+08 | O8: 1.9950442e+09
B9: Aguacate | C9: 17107564 | D9: 16804240 | E9: 11489011 | F9: 12287334 | G9: 18898531 | H9: 17044168 | I9: 22416829 | J9: 19817959 | K9: 15980033 | L9: 13800333 | M9: 9710231.4 | N9: 15986619 | O9: 1.9134285e+08
B10: Aniana Vargas | C10: 155905.53 | D10: 97931.658 | E10: 101685.43 | F10: 128508.54 | G10: 139659.3 | H10: 109272.36 | I10: 121248.24 | J10: 106713.57 | K10: 99304.523 | L10: 79833.166 | M10: 130980.9 | N10: 132076.38 | O10: 1403119.6
B11: Baiguaque | C11: 159405.03 | D11: 90444.221 | E11: 108744.72 | F11: 288255.28 | G11: 358173.87 | H11: 262543.72 | I11: 118956.78 | J11: 66269.347 | K11: 45497.487 | L11: 82119.598 | M11: 227710.55 | N11: 194500.5 | O11: 2002621.1
B12: Barahona Carbón | C12: 29163393 | D12: 23449584 | E12: 21370233 | F12: 23204957 | G12: 29652861 | H12: 31214720 | I12: 34185137 | J12: 35282719 | K12: 35141865 | L12: 30720922 | M12: 19747269 | N12: 12916613 | O12: 3.2605027e+08
B13: Bersal | C13: 0 | D13: 0 | E13: 175168.23 | F13: 0 | G13: 496551.54 | H13: 1786241.8 | I13: 1624101.4 | J13: 108799.92 | K13: 1433190.6 | L13: 1186333.2 | M13: 240949.4 | N13: 177428.49 | O13: 7228764.6
B14: Brazo Derecho | C14: 570991.7 | D14: 470391.78 | E14: 512692.28 | F14: 560952.26 | G14: 627571.33 | H14: 785591.83 | I14: 553046.2 | J14: 466420.62 | K14: 571642.45 | L14: 534360.59 | M14: 195983.48 | N14: 632.20938 | O14: 5850276.7
B15: Calabaza | C15: 8432345.2 | D15: 7933507.3 | E15: 8953966.7 | F15: 8219941.2 | G15: 7866429.8 | H15: 7575799.5 | I15: 8136558 | J15: 9015403.6 | K15: 8504058.4 | L15: 8287134.6 | M15: 5687580.1 | N15: 8012956.9 | O15: 96625681
B16: Central Termoeléctrica Punta Catalina | C16: 4.5039202e+08 | D16: 3.8411959e+08 | E16: 3.9172468e+08 | F16: 4.9731219e+08 | G16: 4.888116e+08 | H16: 2.9776787e+08 | I16: 3.2039483e+08 | J16: 5.1126804e+08 | K16: 4.2780877e+08 | L16: 4.9583594e+08 | M16: 4.8297891e+08 | N16: 4.8765407e+08 | O16: 5.2360685e+09
B17: CEPP | C17: 0 | D17: 0 | E17: 0 | F17: 0 | G17: 0 | H17: 0 | I17: 0 | J17: 0 | K17: 0 | L17: 0 | M17: 0 | N17: 0 | O17: 0
B18: CESPM | C18: 1.6085101e+08 | D18: 1.5774381e+08 | E18: 1.1888836e+08 | F18: 1.6956147e+08 | G18: 1.7094022e+08 | H18: 1.7328161e+08 | I18: 1.6675339e+08 | J18: 1.8074499e+08 | K18: 1.8369372e+08 | L18: 1.7980061e+08 | M18: 1.5831212e+08 | N18: 1.6558699e+08 | O18: 1.9861583e+09
B19: Cumayasa I | C19: 8940787.4 | D19: 9229477.1 | E19: 11295056 | F19: 10626849 | G19: 10453568 | H19: 9976802 | I19: 10181583 | J19: 10882504 | K19: 9932057.3 | L19: 9419269 | M19: 7035223.8 | N19: 7818835.2 | O19: 1.1579201e+08
... B38: Magueyal | C38: 0 | D38: 0 | E38: 6553.7688 | F38: 0 | G38: 88156.784 | H38: 99871.357 | I38: 0 | J38: 0 | K38: 0 | L38: 0 | M38: 0 | N38: 90485.427 | O38: 285067.34
B39: Maranatha | H39: 416600.58 | I39: 729991.95 | J39: 1342028.9 | K39: 1365233.4 | L39: 1518450.4 | M39: 1061334.4 | N39: 1182054.1 | O39: 7615693.7
B40: Matrisol | C40: 6306266.2 | D40: 6702483.5 | E40: 7754049.3 | F40: 6660558.6 | G40: 6923312.8 | H40: 7512889.3 | I40: 7642075.4 | J40: 7714673.4 | K40: 7129021.8 | L40: 6783901.7 | M40: 5059647.2 | N40: 5059647.2 | O40: 81248526
B41: Metaldom | C41: 354706.22 | D41: 915195.67 | E41: 7997964.8 | F41: 1133667.9 | G41: 8238954.9 | H41: 20028422 | I41: 17050532 | J41: 13591277 | K41: 17667640 | L41: 18022516 | M41: 4980142.3 | N41: 2860898.8 | O41: 1.1284192e+08
B42: Monción | C42: 11526929 | D42: 11061882 | E42: 12348048 | F42: 10342540 | G42: 8620968 | H42: 9364467 | I42: 12672924 | J42: 12068403 | K42: 10139304 | L42: 10923243 | M42: 9105709.2 | N42: 17681078 | O42: 1.3585549e+08
B43: Monte Plata Solar | C43: 3453607 | D43: 3543212.6 | E43: 4141915.3 | F43: 2927858.9 | G43: 3665021.2 | H43: 3455238.3 | I43: 3054828.2 | J43: 6715547.2 | K43: 8794321.8 | L43: 8905602.6 | M43: 6836654.2 | N43: 7934893.3 | O43: 63428701
B44: Monte Río | C44: 2529927.8 | D44: 9993223.3 | E44: 21214990 | F44: 6245084.7 | G44: 28827724 | H44: 53369667 | I44: 43187221 | J44: 30590735 | K44: 46236945 | L44: 49111414 | M44: 20835095 | N44: 6215657.1 | O44: 3.1835768e+08
B45: Montecristi Solar | C45: 7532178.7 | D45: 7152190.5 | E45: 9105629.8 | F45: 8596689.3 | G45: 8244472.7 | H45: 7692052.2 | I45: 8227223.3 | J45: 8905655.7 | K45: 8196543.3 | L45: 7447102.7 | M45: 6303845.7 | N45: 6167382.5 | O45: 93570967
B46: Nizao-Najayo | C46: 0 | D46: 0 | E46: 0 | F46: 0 | G46: 0 | H46: 18040.201 | I46: 1774.8744 | J46: 81.407035 | K46: 0 | L46: 0 | M46: 0 | N46: 0 | O46: 19896.482
B47: Palamara | C47: 9484150 | D47: 14068999 | E47: 28470086 | F47: 7292033.2 | G47: 13006833 | H47: 43381272 | I47: 48654821 | J47: 38739458 | K47: 47857441 | L47: 39128975 | M47: 14741407 | N47: 16416854 | O47: 3.2124233e+08
B48: Palenque BT | C48: 10279.055 | D48: 739479.82 | E48: 1881816 | F48: 525822.1 | G48: 3421649.2 | H48: 9841749.2 | I48: 8012351.8 | J48: 692204.69 | K48: 6011686.5 | L48: 6773296.3 | M48: 1942397.3 | N48: 795715.16 | O48: 40648447
B49: Palomino | C49: 6777382.3 | D49: 5903763.9 | E49: 5312580.7 | F49: 6564769.4 | G49: 11737162 | H49: 16764616 | I49: 12368153 | J49: 10498414 | K49: 13034354 | L49: 18186752 | M49: 14386667 | N49: 9321606.8 | O49: 1.3085622e+08
B50: Parque Energético Los Mina | C50: 1.6517599e+08 | D50: 1.5250904e+08 | E50: 1.6654279e+08 | F50: 1.4455102e+08 | G50: 1.7089725e+08 | H50: 1.9439786e+08 | I50: 1.9894431e+08 | J50: 1.6042735e+08 | K50: 68735244 | L50: 1.737051e+08 | M50: 1.7030288e+08 | N50: 1.7131881e+08 | O50: 1.9375076e+09
B51: Parque Eólico Agua Clara | C51: 12974156 | D51: 7562927.2 | E51: 10944737 | F51: 11249888 | G51: 8099412.3 | H51: 10899424 | I51: 19011831 | J51: 16189677 | K51: 11231387 | L51: 6251478 | M51: 7120616.8 | N51: 8062623.9 | O51: 1.2959816e+08
... B60: Parque Fotovoltaico Esperanza | C60: 13973873 | D60: 13042593 | E60: 17981104 | F60: 16212657 | G60: 16628239 | H60: 16578571 | I60: 17335024 | J60: 19365892 | K60: 16649113 | L60: 14353708 | M60: 11072138 | N60: 11872912 | O60: 1.8506583e+08
B61: Parque Fotovoltaico La Victoria | M61: 677054.59 | N61: 6928941.5 | O61: 7605996
B62: Parque Fotovoltaico Los Negros | C62: 3408981.4 | D62: 3112886.3 | E62: 4034529.6 | F62: 3822689.9 | G62: 3670271.3 | H62: 3774313.8 | I62: 4012446.5 | J62: 2659380.5 | K62: 3352047.8 | L62: 3794670.7 | M62: 2626130.2 | N62: 3085564.3 | O62: 41353912
B63: Parque Fotovoltaico Mata de Palma | C63: 7419675.8 | D63: 7560085.2 | E63: 8729328.8 | F63: 6977065.2 | G63: 7818375.3 | H63: 7355227.5 | I63: 7519943.7 | J63: 7860723.8 | K63: 7782100 | L63: 8103605.7 | M63: 6177813.5 | N63: 7311312 | O63: 90615256
B64: Parque Fotovoltaico Mirasol | N64: 5034118.1 | O64: 5034118.1
B65: Parque Fotovoltaico Sajoma | C65: 0 | D65: 0 | E65: 0 | F65: 0 | G65: 0 | H65: 0 | I65: 0 | J65: 2714254.7 | K65: 12643741 | L65: 11332655 | M65: 9054069.6 | N65: 9955376.2 | O65: 45700097
B66: Parque Solar Canoa | C66: 4511586.5 | D66: 4649681.1 | E66: 5420980.3 | F66: 5035754.4 | G66: 4951064.5 | H66: 4678170.2 | I66: 5067564.5 | J66: 6071447.7 | K66: 5393996.2 | L66: 5489825.9 | M66: 3909012.6 | N66: 4965691.1 | O66: 60144775
B67: Parque Solar el Soco | C67: 9497097.6 | D67: 9366258.5 | E67: 11126391 | F67: 9619089 | G67: 10495871 | H67: 9650583.7 | I67: 9550917 | J67: 9552159.2 | K67: 9234265.3 | L67: 10215871 | M67: 7671783.2 | N67: 8649211.6 | O67: 1.146295e+08
B68: Parque Solar Girasol | C68: 14691954 | D68: 16916475 | E68: 20193131 | F68: 20173337 | G68: 19404643 | H68: 17275435 | I68: 18388010 | J68: 20475332 | K68: 19070810 | L68: 18522244 | M68: 11502480 | N68: 15873204 | O68: 2.1248706e+08
...

Sheet Consumos Propio
B2: Comisión Nacional de Energía
B3: Sistema de Información Energética Nacional
B4: Consumos propios de energía eléctrica según central y Mes, 2024
B5: (en kWh)
B7: Central | C7: Enero | D7: Febrero | E7: Marzo | F7: Abril | G7: Mayo | H7: Junio | I7: Julio | J7: Agosto | K7: Septiembre | L7: Octubre | M7: Noviembre | N7: Diciembre | O7: Total
B8: AES Andrés | C8: 3215816.5 | D8: 4982915 | E8: 5793014 | F8: 4872705.5 | G8: 4751248.5 | H8: 4261841.8 | I8: 5599109.8 | J8: 5731998.4 | K8: 5531258.4 | L8: 5934173.7 | M8: 5173202.7 | N8: 4004042.5 | O8: 59851327
B9: Aguacate | C9: 85537.82 | D9: 84021.201 | E9: 57445.056 | F9: 61436.672 | G9: 94492.656 | H9: 85220.841 | I9: 112084.14 | J9: 99089.796 | K9: 79900.166 | L9: 69001.663 | M9: 48551.157 | N9: 79933.095 | O9: 956714.27
B10: Aniana Vargas | C10: 779.52764 | D10: 489.65829 | E10: 508.42714 | F10: 642.54271 | G10: 698.29648 | H10: 546.36181 | I10: 606.24121 | J10: 533.56784 | K10: 496.52261 | L10: 399.16583 | M10: 654.90452 | N10: 660.38191 | O10: 7015.598
B11: Baiguaque | C11: 797.02513 | D11: 452.22111 | E11: 543.72362 | F11: 1441.2764 | G11: 1790.8693 | H11: 1312.7186 | I11: 594.78392 | J11: 331.34673 | K11: 227.48744 | L11: 410.59799 | M11: 1138.5528 | N11: 972.50251 | O11: 10013.106
B12: Barahona Carbón | C12: 2041437.5 | D12: 1641470.9 | E12: 1495916.3 | F12: 1624347 | G12: 2075700.2 | H12: 2185030.4 | I12: 2392959.6 | J12: 2469790.3 | K12: 2459930.6 | L12: 2150464.5 | M12: 1382308.8 | N12: 904162.94 | O12: 22823519
B13: Bersal | C13: 0 | D13: 0 | E13: 4554.3741 | F13: 0 | G13: 12910.34 | H13: 46442.287 | I13: 42226.637 | J13: 2828.7978 | K13: 37262.956 | L13: 30844.663 | M13: 6264.6844 | N13: 4613.1408 | O13: 187947.88
B14: Brazo Derecho | C14: 2854.9585 | D14: 2351.9589 | E14: 2563.4614 | F14: 2804.7613 | G14: 3137.8566 | H14: 3927.9592 | I14: 2765.231 | J14: 2332.1031 | K14: 2858.2122 | L14: 2671.803 | M14: 979.91741 | N14: 3.1610469 | O14: 29251.384
B15: Calabaza | C15: 18635.483 | D15: 17533.051 | E15: 19788.266 | F15: 18166.07 | G15: 17384.81 | H15: 16742.517 | I15: 17981.793 | J15: 19924.042 | K15: 18793.969 | L15: 18314.568 | M15: 12569.552 | N15: 17708.635 | O15: 213542.76
B16: Central Termoeléctrica Punta Catalina | C16: 28239580 | D16: 24084298 | E16: 24561137 | F16: 31181474 | G16: 30648487 | H16: 18670046 | I16: 20088756 | J16: 32056506 | K16: 26823610 | L16: 31088913 | M16: 30282778 | N16: 30575910 | O16: 3.283015e+08
B17: CEPP | C17: 0 | D17: 0 | E17: 0 | F17: 0 | G17: 0 | H17: 0 | I17: 0 | J17: 0 | K17: 0 | L17: 0 | M17: 0 | N17: 0 | O17: 0
B18: CESPM | C18: 4005165.4 | D18: 3917182.2 | E18: 2931514.5 | F18: 4215390.1 | G18: 4250145.2 | H18: 4311450.5 | I18: 4147216.7 | J18: 4494335.3 | K18: 4568134.6 | L18: 4475118.7 | M18: 3941228.2 | N18: 4109688.1 | O18: 49366569
B19: Cumayasa I | C19: 11175.984 | D19: 11536.846 | E19: 14118.82 | F19: 13283.562 | G19: 13066.96 | H19: 12471.003 | I19: 12726.979 | J19: 13603.13 | K19: 12415.072 | L19: 11774.086 | M19: 8794.0297 | N19: 9773.5439 | O19: 144740.02
... B60: Parque Fotovoltaico Esperanza | C60: 33509.348 | D60: 31276.138 | E60: 43118.687 | F60: 38877.951 | G60: 39874.517 | H60: 39755.413 | I60: 41569.387 | J60: 46439.409 | K60: 39924.572 | L60: 34420.193 | M60: 26550.988 | N60: 28471.244 | O60: 443787.85
B61: Parque Fotovoltaico La Victoria | M61: 0 | N61: 0 | O61: 0
B62: Parque Fotovoltaico Los Negros | C62: 30067.216 | D62: 27455.657 | E62: 35584.551 | F62: 33716.125 | G62: 32371.793 | H62: 33289.448 | I62: 35389.778 | J62: 23455.736 | K62: 29565.061 | L62: 33468.996 | M62: 23162.469 | N62: 27214.677 | O62: 364741.51
B63: Parque Fotovoltaico Mata de Palma | C63: 7419.6758 | D63: 7560.0852 | E63: 8729.3288 | F63: 6977.0652 | G63: 7818.3753 | H63: 7355.2275 | I63: 7519.9437 | J63: 7860.7238 | K63: 7782.1 | L63: 8103.6057 | M63: 6177.8135 | N63: 7311.312 | O63: 90615.256
B64: Parque Fotovoltaico Mirasol | N64: 0 | O64: 0
B65: Parque Fotovoltaico Sajoma | C65: 0 | D65: 0 | E65: 0 | F65: 0 | G65: 0 | H65: 0 | I65: 0 | J65: 0 | K65: 0 | L65: 0 | M65: 0 | N65: 0 | O65: 0
B66: Parque Solar Canoa | C66: 10827.808 | D66: 11159.235 | E66: 13010.353 | F66: 12085.811 | G66: 11882.555 | H66: 11227.608 | I66: 12162.155 | J66: 14571.475 | K66: 12945.591 | L66: 13175.582 | M66: 9381.6301 | N66: 11917.659 | O66: 144347.46
B67: Parque Solar el Soco | C67: 18994.195 | D67: 18732.517 | E67: 22252.783 | F67: 19238.178 | G67: 20991.742 | H67: 19301.167 | I67: 19101.834 | J67: 19104.318 | K67: 18468.531 | L67: 20431.742 | M67: 15343.566 | N67: 17298.423 | O67: 229259
B68: Parque Solar Girasol | C68: 39668.276 | D68: 45674.483 | E68: 54521.453 | F68: 54468.011 | G68: 52392.537 | H68: 46643.674 | I68: 49647.628 | J68: 55283.397 | K68: 51491.186 | L68: 50010.058 | M68: 31056.696 | N68: 42857.652 | O68: 573715.05
B69: Parque Solar Santanasol | C69: 24945.633 | D69: 25602.228 | E69: 29205.25 | F69: 28607.375 | G69: 26817.08 | H69: 24537.639 | I69: 25427.939 | J69: 28842.305 | K69: 28100.369 | L69: 28486.328 | M69: 17995.943 | N69: 24151.993 | O69: 312720.08
B70: Pimentel | C70: 496686.9 | D70: 402811.77 | E70: 771800.87 | F70: 682473.14 | G70: 825520.04 | H70: 954240.74 | I70: 966903.32 | J70: 927308.99 | K70: 1029281.6 | L70: 994533.7 | M70: 730506.67 | N70: 389678.62 | O70: 9171746.3
B71: Pinalito | C71: 43200.576 | D71: 28967.99 | E71: 22152.6 | F71: 23075.792 | G71: 56470.722 | H71: 37993.268 | I71: 38688.955 | J71: 38959.164 | K71: 40611.257 | L71: 24137.607 | M71: 61586.154 | N71: 37207.886 | O71: 453051.97
B72: Powership | C72: 51201.749 | D72: 162722.79 | E72: 621605.75 | F72: 515986.06 | G72: 1363582 | H72: 3103765.8 | I72: 3037300.4 | J72: 824735.53 | K72: 3209665.5 | L72: 3245448 | M72: 1458615.9 | N72: 659075.86 | O72: 18253705
B73: Quisqueya 1 | C73: 700921.56 | D73: 869948.47 | E73: 833958.01 | F73: 949056.09 | G73: 888554.17 | H73: 785144.87 | I73: 974306.05 | J73: 964861.3 | K73: 927954.86 | L73: 995749.84 | M73: 959440.34 | N73: 898461.28 | O73: 10748357
B74: Quisqueya 2 | C74: 2131296.5 | D74: 2128598.6 | E74: 2460201.7 | F74: 2070503.9 | G74: 2407963.2 | H74: 2540474.2 | I74: 2449811.2 | J74: 2457682.4 | K74: 2433453.8 | L74: 2425259.9 | M74: 2338768.1 | N74: 2323807.9 | O74: 28167821
B75: Rincón | C75: 8298.2908 | D75: 7206.179 | E75: 5044.5858 | F75: 13084.268 | G75: 22516.167 | H75: 9183.3085 | I75: 8825.6573 | J75: 7812.596 | K75: 4834.0823 | L75: 2943.3753 | M75: 10651.884 | N75: 15074.732 | O75: 115475.13
B76: Río Blanco | C76: 51789.595 | D76: 33368.279 | E76: 28197.959 | F76: 42544.028 | G76: 66629.966 | H76: 45405.349 | I76: 56023.162 | J76: 49546.118 | K76: 45910.226 | L76: 34856.381 | M76: 63278.652 | N76: 50729.034 | O76: 568278.75
... B88: Valdesia | C88: 19958.161 | D88: 17049.622 | E88: 17552.385 | F88: 17975.394 | G88: 15462.04 | H88: 33652.078 | I88: 33862.797 | J88: 39093.014 | K88: 23424.169 | L88: 14364.287 | M88: 13622.499 | N88: 16051.744 | O88: 262068.19
B89: Total | C89: =SUM(C8:C88) -> 68013664 | D89: =SUM(D8:D88) -> 56069621 | E89: =SUM(E8:E88) -> 64853350 | F89: =SUM(F8:F88) -> 71334558 | G89: =SUM(G8:G88) -> 74038120 | H89: =SUM(H8:H88) -> 67775007 | I89: =SUM(I8:I88) -> 70038528 | J89: =SUM(J8:J88) -> 80511428 | ... O89: =SUM(O8:O88) -> 8.4014247e+08
B91: Nota¹: Los datos de consumo de estación corresponden la cantidad de energía utilizada en las instalaciones de las plantas eléctricas.
B92: Nota²: El dato de Sultana del Este, Quisqueya 1 y San Pedro BioEnergy representa el excedente inyectado al sistema (SENI) en lugar de la generación total de la central.
B93: Fuente: Elaboración propia en base a datos suministrados por el Organismo Coordinador del Sistema Eléctrico Nacional Interconectado, 2024.
B96: Verificacion | C96: =[1]!Calc_Consumos_Propios[[#Totals],[Enero]]-'Consumos Propio'!C89 -> 0 | D96: =[1]!Calc_Consumos_Propios[[#Totals],[Febrero]]-'Consumos Propio'!D89 -> 0 | E96: =[1]!Calc_Consumos_Propios[[#Totals],[Marzo]]-'Consumos Propio'!E89 -> 0 | F96: =[1]!Calc_Consumos_Propios[[#Totals],[Abril]]-'Consumos Propio'!F89 -> 0 | G96: =[1]!Calc_Consumos_Propios[[#Totals],[Mayo]]-'Consumos Propio'!G89 -> 0 | H96: =[1]!Calc_Consumos_Propios[[#Totals],[Junio]]-'Consumos Propio'!H89 -> 0 | I96: =[1]!Calc_Consumos_Propios[[#Totals],[Julio]]-'Consumos Propio'!I89 -> 0 | J96: =[1]!Calc_Consumos_Propios[[#Totals],[Agosto]]-'Consumos Propio'!J89 -> 0 | K96: =[1]!Calc_Consumos_Propios[[#Totals],[Septiembre]]-'Consumos Propio'!K89 -> 0 | L96: =[1]!Calc_Consumos_Propios[[#Totals],[Octubre]]-'Consumos Propio'!L89 -> 0 | M96: =[1]!Calc_Consumos_Propios[[#Totals],[Noviembre]]-'Consumos Propio'!M89 -> 0 | N96: =[1]!Calc_Consumos_Propios[[#Totals],[Diciembre]]-'Consumos Propio'!N89 -> 0 | O96: =[1]!Calc_Consumos_Propios[[#Totals],[Total]]-'Consumos Propio'!O89 -> 0
